Workbook
Name JR_PAGE_ANCHOR_0_1: 'PLANILHA ORCAMENTARIA'!$A$1
Name JR_PAGE_ANCHOR_1_1: 'RESUMO'!$A$1
Name JR_PAGE_ANCHOR_2_1: 'COMPOSICOES'!$A$1
Name JR_PAGE_ANCHOR_3_1: 'COMPOSICOES AUXILIARES'!$A$1
Name JR_PAGE_ANCHOR_4_1: 'ENCARGOS SOCIAIS'!$A$1
Name VALOR_TOTAL: 'PLANILHA ORCAMENTARIA'!$H$594
Name FATOR: RESUMO!$H$4
Name BDI: RESUMO!$H$5

Sheet PLANILHA ORCAMENTARIA
A3: ITEM | B3: CÓDIGO | C3: DESCRIÇÃO | D3: FONTE | E3: UND | F3: QUANTIDADE | G3: PREÇO UNITÁRIO R$ | H3: PREÇO TOTAL R$ | K3: PREÇO UNITÁRIO R$
A4: 1 | B4: ADMINISTRAÇÃO LOCAL DA OBRA | H4: =ROUND(SUM(H5:H5),2)
A5: 1.1 | B5: CXXXX | C5: ADMINISTRAÇÃO LOCAL DA OBRA - SEM DESONERAÇÃO, ENCARGOS SOCIAISINCORPORADOS NO PREÇO UNITÁRIO | E5: % | F5: 100 | G5: =COMPOSICOES!G18 | H5: =ROUND(ROUND(F5,2)*ROUND(G5,2),2) | K5: 16341.58 | L5: =G5-K5
A6: 2 | B6: SERVIÇOS INICIAIS | H6: =ROUND(H7+H29+H32+H36+H39,2)
A7: 2.1 | B7: INSTALAÇÃO DO CANTEIRO | H7: =ROUND(H8+H13+H20+H23+H26,2)
A8: 2.1.1 | B8: LIMPEZA DE ÁREA PARA CANTEIRO | H8: =ROUND(SUM(H9:H12),2)
A9: 2.1.1.1 | B9: 98525 | C9: LIMPEZA MECANIZADA DE CAMADA VEGETAL, VEGETAÇÃO E PEQUENAS ÁRVORES (DIÂMETRO DE TRONCO MENOR QUE 0,20 M), COM TRATOR DE ESTEIRAS.AF_03/2024 | D9: SINAPI | E9: M2 | F9: 566.74 | G9: =COMPOSICOES!G30 | H9: =ROUND(ROUND(F9,2)*ROUND(G9,2),2) | K9: 0.69 | L9: =G9-K9
A10: 2.1.1.2 | B10: 100980 | C10: CARGA, MANOBRA E DESCARGA DE SOLOS E MATERIAIS GRANULARES EM CAMINHÃO BASCULANTE 18 M³ - CARGA COM ESCAVADEIRA HIDRÁULICA (CAÇAMBA DE 1,20 M³ / 155 HP) E DESCARGA LIVRE(UNIDADE: M3). AF_07/2020 | D10: SINAPI | E10: M3 | F10: 73.68 | G10: =COMPOSICOES!G41 | H10: =ROUND(ROUND(F10,2)*ROUND(G10,2),2) | K10: 6.57 | L10: =G10-K10
A11: 2.1.1.3 | B11: 95877 | C11: TRANSPORTE COM CAMINHÃO BASCULANTE DE 18 M³, EM VIA URBANA PAVIMENTADA, DMT ATÉ 30 KM (UNIDADE:M3XKM). AF_07/2020 | D11: SINAPI | E11: M3XKM | F11: 368.38 | G11: =COMPOSICOES!G50 | H11: =ROUND(ROUND(F11,2)*ROUND(G11,2),2) | K11: 1.9 | L11: =G11-K11
A12: 2.1.1.4 | B12: C5185 | C12: DESTINAÇÃO FINAL DO RESÍDUO SOLIDO NÃO SEGREGADO EM TERRENOLICENCIADO - SEM TRANSPORTE | D12: SEINFRA | E12: M3 | F12: 73.68 | G12: =COMPOSICOES!G58 | H12: =ROUND(ROUND(F12,2)*ROUND(G12,2),2) | K12: 11.2 | L12: =G12-K12
A13: 2.1.2 | B13: ALOJAMENTO, VESTIÁRIO, ESCRITÓRIO E DEPÓSITO | H13: =ROUND(SUM(H14:H19),2)
A14: 2.1.2.1 | B14: 407PRÓPRIO | C14: BARRACÃO DE OBRA PARA LOJAMENTO/ESCRITÓRIO, PISO EM PINHO 3A, PAREDES EM COMPENSADO 10MM, COBERTURA EM TELHA FIBROCIMENTO 6MM, INCLUSOINSTALAÇÕES ELÉTRICAS E ESQUADRIAS | D14: Composiçõ es Próprias | E14: M² | F14: 25 | G14: =COMPOSICOES!G99 | H14: =ROUND(ROUND(F14,2)*ROUND(G14,2),2) | K14: 501.02 | L14: =G14-K14
A15: 2.1.2.2 | B15: 00010777 | C15: LOCACAO DE CONTAINER 2,30 X 4,30 M, ALT. 2,50 M, PARA SANITARIO, COM 3 BACIAS, 4 CHUVEIROS, 1 LAVATORIO E 1 MICTORIO (NÃO INCLUIMOBILIZACAO/DESMOBILIZACAO) | D15: SINAPI | E15: MES | F15: 8 | G15: =COMPOSICOES!G107 | H15: =ROUND(ROUND(F15,2)*ROUND(G15,2),2) | K15: 1674.73 | L15: =G15-K15
A16: 2.1.2.3 | B16: 00010775 | C16: LOCACAO DE CONTAINER 2,30 X 6,00 M, ALT. 2,50 M, COM 1 SANITARIO, PARA ESCRITORIO, COMPLETO, SEM DIVISORIAS INTERNAS (NAO INCLUIMOBILIZACAO/DESMOBILIZACAO) | D16: SINAPI | E16: MES | F16: 8 | G16: =COMPOSICOES!G115 | H16: =ROUND(ROUND(F16,2)*ROUND(G16,2),2) | K16: 1475 | L16: =G16-K16
A17: 2.1.2.4 | B17: 476 | C17: FRETE (CARGA, MANOBRA, DESCARGA E TRANSPORTE) DE CONTAINER EM CAMINHÃO CARROCERIA COM MUCK - TRAJETO MÁXIMO ATÉ 30KM | D17: Composiçõ | E17: UN | F17: 4 | G17: =COMPOSICOES!G127 | H17: =ROUND(ROUND(F17,2)*ROUND(G17,2),2) | K17: 286.87 | L17: =G17-K17
A18: 2.1.2.5 | B18: C0369 | C18: BARRACÃO ABERTO | D18: SEINFRA | E18: M2 | F18: 30 | G18: =COMPOSICOES!G153 | H18: =ROUND(ROUND(F18,2)*ROUND(G18,2),2) | K18: 151.62 | L18: =G18-K18
A19: 2.1.2.6 | B19: C2936 | C19: REFEITÓRIOS | D19: SEINFRA | E19: M2 | F19: 20 | G19: =COMPOSICOES!G185 | H19: =ROUND(ROUND(F19,2)*ROUND(G19,2),2) | K19: 372.84 | L19: =G19-K19
A20: 2.1.3 | B20: LIGAÇÕES PROVISÓRIAS | H20: =ROUND(SUM(H21:H22),2)
A21: 2.1.3.1 | B21: 369PRÓPRIO | C21: LIGAÇÃO PROVISÓRIA DE ÁGUA E ESGOTO PARA CANTEIRO DE OBRAS | D21: Composiçõ esPróprias | E21: UN | F21: 1 | G21: =COMPOSICOES!G240 | H21: =ROUND(ROUND(F21,2)*ROUND(G21,2),2) | K21: 4304.67 | L21: =G21-K21
A22: 2.1.3.2 | B22: 370PRÓPRIO | C22: LIGAÇÃO PROVISÓRIA LUZ E FORÇA | D22: Composiçõ esPróprias | E22: UN | F22: 1 | G22: =COMPOSICOES!G286 | H22: =ROUND(ROUND(F22,2)*ROUND(G22,2),2) | K22: 5321.9 | L22: =G22-K22
A23: 2.1.4 | B23: SINALIZAÇÃO E SEGURANÇA | H23: =ROUND(SUM(H24:H25),2)
A24: 2.1.4.1 | B24: 103689 | C24: FORNECIMENTO E INSTALAÇÃO DE PLACA DE OBRA COM CHAPA GALVANIZADA EESTRUTURA DE MADEIRA. AF_03/2022_PS | D24: SINAPI | E24: M2 | F24: 24.5 | G24: =COMPOSICOES!G304 | H24: =ROUND(ROUND(F24,2)*ROUND(G24,2),2) | K24: 467.74 | L24: =G24-K24
A25: 2.1.4.2 | B25: 98459 | C25: TAPUME COM TELHA METÁLICA.AF_03/2024 | D25: SINAPI | E25: M2 | F25: 190.68 | G25: =COMPOSICOES!G326 | H25: =ROUND(ROUND(F25,2)*ROUND(G25,2),2) | K25: 98.04 | L25: =G25-K25
A26: 2.1.5 | B26: EQUIPAMENTOS (LOCAÇÃO) | H26: =ROUND(SUM(H27:H28),2)
A27: 2.1.5.1 | B27: 371PRÓPRIO | C27: LOCAÇÃO DE ANDAIME METÁLICO TIPO FACHADEIRO (FORNECIMENTO,MONTAGEM E DESMONTAGEM) | D27: Composiçõ esPróprias | E27: M2XMÊ S | F27: 245.6 | G27: =COMPOSICOES!G338 | H27: =ROUND(ROUND(F27,2)*ROUND(G27,2),2) | K27: 25.97 | L27: =G27-K27
A28: 2.1.5.2 | B28: 97062 | C28: COLOCAÇÃO DE TELA EM ANDAIMEFACHADEIRO. AF_03/2024 | D28: SINAPI | E28: M2 | F28: 122.8 | G28: =COMPOSICOES!G351 | H28: =ROUND(ROUND(F28,2)*ROUND(G28,2),2) | K28: 5.83 | L28: =G28-K28
A29: 2.2 | B29: MOVIMENTO DE TERRA | H29: =ROUND(H30,2)
A30: 2.2.1 | B30: COMPACTAÇÃO DE ATERRO | H30: =ROUND(SUM(H31:H31),2)
A31: 2.2.1.1 | B31: 97083 | C31: COMPACTAÇÃO MECÂNICA DE SOLO PARA EXECUÇÃO DE RADIER, PISO DE CONCRETO OU LAJE SOBRE SOLO, COM COMPACTADOR DE SOLOS A PERCUSSÃO.AF_09/2021 | D31: SINAPI | E31: M2 | F31: 566.74 | G31: =COMPOSICOES!G364 | H31: =ROUND(ROUND(F31,2)*ROUND(G31,2),2) | K31: 3.65 | L31: =G31-K31
A32: 2.3 | B32: LOCAÇÃO DA OBRA | H32: =ROUND(H33,2)
A33: 2.3.1 | B33: EXECUÇÃO DE GABARITO | H33: =ROUND(SUM(H34:H35),2)
A34: 2.3.1.1 | B34: 99059 | C34: LOCAÇÃO CONVENCIONAL DE OBRA, UTILIZANDO GABARITO DE TÁBUAS CORRIDAS PONTALETADAS A CADA 2,00M -2 UTILIZAÇÕES. AF_03/2024 | D34: SINAPI | E34: M | F34: 101.88 | G34: =COMPOSICOES!G387 | H34: =ROUND(ROUND(F34,2)*ROUND(G34,2),2) | K34: 69.64 | L34: =G34-K34
A35: 2.3.1.2 | B35: C2873 | C35: LOCAÇÃO DA OBRA COM AUXÍLIOTOPOGRÁFICO (ÁREA ATÉ 5000 M2) | D35: SEINFRA | E35: M2 | F35: 566.74 | G35: =COMPOSICOES!G402 | H35: =ROUND(ROUND(F35,2)*ROUND(G35,2),2) | K35: 0.3 | L35: =G35-K35
A36: 2.4 | B36: LICENCIAMENTO AMBIENTAL | H36: =ROUND(SUM(H37:H38),2)
A37: 2.4.1 | B37: SOP1982 | C37: AUTORIZAÇÃO DE SUPRESSÃO DE VEGETAÇÃO (ASV) (IMPLANTAÇÃO DE ATIVIDADES E OBRAS DE UTILIDADE PÚBLICA E INTERESSE SOCIAL) - BDI =14,00 - BDI = 14,00 | D37: Composiçõ es Próprias | E37: UN | F37: 1 | G37: =COMPOSICOES!G410 | H37: =ROUND(ROUND(F37,2)*ROUND(G37,2),2) | K37: 1815.2 | L37: =G37-K37
A38: 2.4.2 | B38: SOP1988 | C38: TAXA PARA LICENCIAMENTO AMBIENTAL, CONFORME RESOLUÇÃO COEMA Nº02/2019 – ATIVIDADE 25.02 - BDI = 14,00 - BDI = 14,00 | D38: Composiçõ esPróprias | E38: UN | F38: 1 | G38: =COMPOSICOES!G418 | H38: =ROUND(ROUND(F38,2)*ROUND(G38,2),2) | K38: 5105.07 | L38: =G38-K38
A39: 2.5 | B39: MOBILIZAÇÃO DA OBRA | H39: =ROUND(SUM(H40:H40),2)
A40: 2.5.1 | B40: C4990 | C40: MOBILIZAÇÃO DE EQUIPAMENTOS EMCAMINHÃO EQUIPADO COM GUINDASTE | D40: SEINFRA | E40: KM | F40: 90.9 | G40: =COMPOSICOES!G426 | H40: =ROUND(ROUND(F40,2)*ROUND(G40,2),2) | K40: 3.2 | L40: =G40-K40
A41: 3 | B41: FUNDAÇÕES | H41: =ROUND(H42+H54+H63+H67+H71,2)
A42: 3.1 | B42: SERVIÇOS GERAIS EM FUNDAÇÕES | H42: =ROUND(H43+H46+H48+H51,2)
...

Sheet RESUMO
A4: 1 | B4: ADMINISTRAÇÃO LOCAL DA OBRA | D4: ='PLANILHA ORCAMENTARIA'!H4 | E4: =(D4/$D$23)*100 | G4: FATOR | H4: 1
A5: 2 | B5: SERVIÇOS INICIAIS | D5: ='PLANILHA ORCAMENTARIA'!H6 | E5: =(D5/$D$23)*100 | G5: BDI | H5: 22,98%
A6: 3 | B6: FUNDAÇÕES | D6: ='PLANILHA ORCAMENTARIA'!H41 | E6: =(D6/$D$23)*100
A7: 4 | B7: SUPERESTRUTURA | D7: ='PLANILHA ORCAMENTARIA'!H74 | E7: =(D7/$D$23)*100
A8: 5 | B8: COBERTURA | D8: ='PLANILHA ORCAMENTARIA'!H101 | E8: =(D8/$D$23)*100
A9: 6 | B9: PAREDES E PAINÉIS | D9: ='PLANILHA ORCAMENTARIA'!H125 | E9: =(D9/$D$23)*100
A10: 7 | B10: ESQUADRIAS | D10: ='PLANILHA ORCAMENTARIA'!H146 | E10: =(D10/$D$23)*100
A11: 8 | B11: SISTEMAS HIDRÁULICOS, SANITÁRIOS E DE COMBATE A INCÊNDIO (HSI) | D11: ='PLANILHA ORCAMENTARIA'!H158 | E11: =(D11/$D$23)*100
A12: 9 | B12: SISTEMA ELÉTRICO (ELE) + SISTEMA DE VOZ E DADOS (NET) | D12: ='PLANILHA ORCAMENTARIA'!H277 | E12: =(D12/$D$23)*100
A13: 10 | B13: SISTEMAS DE AR CONDICIONADO, VENTILAÇÃO E EXAUSTÃO (ACD) | D13: ='PLANILHA ORCAMENTARIA'!H391 | E13: =(D13/$D$23)*100
A14: 11 | B14: REVESTIMENTOS PRIMÁRIOS | D14: ='PLANILHA ORCAMENTARIA'!H426 | E14: =(D14/$D$23)*100
A15: 12 | B15: ACABAMENTOS (REVESTIMENTO PARA TETO, PAREDE E PISO) | D15: ='PLANILHA ORCAMENTARIA'!H437 | E15: =(D15/$D$23)*100
A16: 13 | B16: ACABAMENTOS (HIDROSSANITÁRIOS) | D16: ='PLANILHA ORCAMENTARIA'!H455 | E16: =(D16/$D$23)*100
A17: 14 | B17: ACABAMENTOS (ELÉTRICOS, VOZ, DADOS E TV) | D17: ='PLANILHA ORCAMENTARIA'!H506 | E17: =(D17/$D$23)*100
A18: 15 | B18: PINTURA | D18: ='PLANILHA ORCAMENTARIA'!H538 | E18: =(D18/$D$23)*100
A19: 16 | B19: URBANIZAÇÃO | D19: ='PLANILHA ORCAMENTARIA'!H549 | E19: =(D19/$D$23)*100
A20: 17 | B20: DESMOBILIZAÇÃO DE CANTEIRO | D20: ='PLANILHA ORCAMENTARIA'!H558 | E20: =(D20/$D$23)*100
A21: 18 | B21: SERVIÇOS NÃO FINANCIADOS PELO CONTRATO DE REPASSE | D21: ='PLANILHA ORCAMENTARIA'!H591 | E21: =(D21/$D$23)*100
A22: 19 | B22: Benefícios e Despesas Indiretas (BDI) | D22: ='PLANILHA ORCAMENTARIA'!H592 | E22: 0
C23: VALOR BDI TOTAL: | D23: ='PLANILHA ORCAMENTARIA'!H593 | E23: 100
C24: VALOR ORÇAMENTO: | D24: 3225595.3
C25: VALOR TOTAL: | D25: 3969434.3

Sheet COMPOSICOES
A3: 1.1. ​CXXXX​ ADMINISTRAÇÃO LOCAL DA OBRA - SEM DESONERAÇÃO, ENCARGOS SOCIAISINCORPORADOS NO PREÇO UNITÁRIO​ (%)
A4: COTAÇÃO / ADMINISTRAÇÃO LOCAL DE OBRA (C/ ENCARGOS) | C4: FONTE | D4: UNID | E4: COEFICIENTE | F4: PREÇO UNITÁRIO | G4: TOTAL
A5: I8610 | B5: COMPUTADOR | C5: SEINFRA | D5: UNxMÊS | E5: 1 | F5: 170 | G5: =ROUND(ROUND(E5,8)*F5,2) | L5: 1 | M5: 170 | N5: =(M5-F5)
E6: TOTAL COTAÇÃO / ADMINISTRAÇÃO LOCAL DE OBRA (C/ ENCARGOS): | G6: =SUM(G5:G5)
A7: Mão de Obra | C7: FONTE | D7: UNID | E7: COEFICIENTE | F7: PREÇO UNITÁRIO | G7: TOTAL
A8: I8601 | B8: CADISTA | C8: SEINFRA | D8: MÊS | E8: =L8*FATOR | F8: 5851.46 | G8: =ROUND(ROUND(E8,8)*F8,2) | L8: 0.1 | M8: 5851.46 | N8: =(M8-F8)
A9: I8617 | B9: VIGIA | C9: SEINFRA | D9: MÊS | E9: =L9*FATOR | F9: 3687.34 | G9: =ROUND(ROUND(E9,8)*F9,2) | L9: 1 | M9: 3687.34 | N9: =(M9-F9)
E10: TOTAL Mão de Obra: | G10: =SUM(G8:G9)
A11: Mão de Obra com Encargos Complementares | C11: FONTE | D11: UNID | E11: COEFICIENTE | F11: PREÇO UNITÁRIO | G11: TOTAL
A12: 93563 | B12: ALMOXARIFE COM ENCARGOS COMPLEMENTARES | C12: SINAPI | D12: MES | E12: =L12*FATOR | F12: ='COMPOSICOES AUXILIARES'!G123 | G12: =ROUND(ROUND(E12,8)*F12,2) | L12: 1 | M12: 4298.73 | N12: =(M12-F12)
A13: 93572 | B13: ENCARREGADO GERAL DE OBRAS COM ENCARGOS COMPLEMENTARES | C13: SINAPI | D13: MES | E13: =L13*FATOR | F13: ='COMPOSICOES AUXILIARES'!G1905 | G13: =ROUND(ROUND(E13,8)*F13,2) | L13: 1 | M13: 5117.87 | N13: =(M13-F13)
A14: 93567 | B14: ENGENHEIRO CIVIL DE OBRA PLENO COM ENCARGOS COMPLEMENTARES | C14: SINAPI | D14: MES | E14: =L14*FATOR | F14: ='COMPOSICOES AUXILIARES'!G1948 | G14: =ROUND(ROUND(E14,8)*F14,2) | L14: 0.1 | M14: 24824.87 | N14: =(M14-F14)
E15: TOTAL Mão de Obra com Encargos Complementares: | G15: =SUM(G12:G14)
E16: VALOR: | G16: =SUM(G10,G15)
E17: VALOR BDI (23.08%): | G17: =ROUNDDOWN(G16*BDI,2)
E18: VALOR COM BDI: | G18: =G17 + G16
A20: 2.1.1.1. ​98525​ LIMPEZA MECANIZADA DE CAMADA VEGETAL, VEGETAÇÃO E PEQUENAS ÁRVORES (DIÂMETRO DE TRONCO MENOR QUE 0,20 M), COM TRATOR DE ESTEIRAS.AF_03/2024​ (M2)
A21: Equipamento Custo Horário | C21: FONTE | D21: UNID | E21: COEFICIENTE | F21: PREÇO UNITÁRIO | G21: TOTAL
A22: 89031 | B22: TRATOR DE ESTEIRAS, POTÊNCIA 100 HP, PESO OPERACIONAL 9,4 T, COM LÂMINA 2,19 M3 - CHI DIURNO. AF_06/2014 | C22: SINAPI | D22: CHI | E22: 0.0029 | F22: ='COMPOSICOES AUXILIARES'!G3615 | G22: =TRUNC(TRUNC(E22,8)*F22,2) | L22: 0.0029 | M22: 83.96 | N22: =(M22-F22)
A23: 89032 | B23: TRATOR DE ESTEIRAS, POTÊNCIA 100 HP, PESO OPERACIONAL 9,4 T, COM LÂMINA 2,19 M3 - CHP DIURNO. AF_06/2014 | C23: SINAPI | D23: CHP | E23: 0.0017 | F23: ='COMPOSICOES AUXILIARES'!G3629 | G23: =TRUNC(TRUNC(E23,8)*F23,2) | L23: 0.0017 | M23: 206.64 | N23: =(M23-F23)
E24: TOTAL Equipamento Custo Horário: | G24: =SUM(G22:G23)
A25: Mão de Obra com Encargos Complementares | C25: FONTE | D25: UNID | E25: COEFICIENTE | F25: PREÇO UNITÁRIO | G25: TOTAL
A26: 88441 | B26: JARDINEIRO COM ENCARGOS COMPLEMENTARES | C26: SINAPI | D26: H | E26: =L26*FATOR | F26: ='COMPOSICOES AUXILIARES'!G2344 | G26: =TRUNC(TRUNC(E26,8)*F26,2) | L26: 0.0046 | M26: 23.91 | N26: =(M26-F26)
E27: TOTAL Mão de Obra com Encargos Complementares: | G27: =SUM(G26:G26)
E28: VALOR: | G28: =SUM(G24,G27)
E29: VALOR BDI (23.08%): | G29: =ROUNDDOWN(G28*BDI,2)
E30: VALOR COM BDI: | G30: =G29 + G28
A32: 2.1.1.2. ​100980​ CARGA, MANOBRA E DESCARGA DE SOLOS E MATERIAIS GRANULARES EM CAMINHÃO BASCULANTE 18 M³ - CARGA COM ESCAVADEIRA HIDRÁULICA (CAÇAMBA DE 1,20 M³ / 155 HP) E DESCARGA LIVRE(UNIDADE: M3). AF_07/2020​ (M3)
A33: Equipamento Custo Horário | C33: FONTE | D33: UNID | E33: COEFICIENTE | F33: PREÇO UNITÁRIO | G33: TOTAL
A34: 89884 | B34: CAMINHÃO BASCULANTE 18 M3, COM CAVALO MECÂNICO DE CAPACIDADE MÁXIMA DE TRAÇÃO COMBINADO DE 45000 KG, POTÊNCIA 330 CV, INCLUSIVE SEMIREBOQUE COM CAÇAMBA METÁLICA - CHI DIURNO. AF_12/2014 | C34: SINAPI | D34: CHI | E34: 0.0077 | F34: ='COMPOSICOES AUXILIARES'!G738 | G34: =TRUNC(TRUNC(E34,8)*F34,2) | L34: 0.0077 | M34: 98.1 | N34: =(M34-F34)
A35: 89883 | B35: CAMINHÃO BASCULANTE 18 M3, COM CAVALO MECÂNICO DE CAPACIDADE MÁXIMA DE TRAÇÃO COMBINADO DE 45000 KG, POTÊNCIA 330 CV, INCLUSIVE SEMIREBOQUE COM CAÇAMBA METÁLICA - CHP DIURNO. AF_12/2014 | C35: SINAPI | D35: CHP | E35: 0.0111 | F35: ='COMPOSICOES AUXILIARES'!G753 | G35: =TRUNC(TRUNC(E35,8)*F35,2) | L35: 0.0111 | M35: 373.41 | N35: =(M35-F35)
A36: 88908 | B36: ESCAVADEIRA HIDRÁULICA SOBRE ESTEIRAS, CAÇAMBA 1,20 M3, PESO OPERACIONAL 21 T, POTÊNCIA BRUTA 155 HP - CHI DIURNO. AF_06/2014 | C36: SINAPI | D36: CHI | E36: 0.0056 | F36: ='COMPOSICOES AUXILIARES'!G1978 | G36: =TRUNC(TRUNC(E36,8)*F36,2) | L36: 0.0056 | M36: 104.69 | N36: =(M36-F36)
A37: 88907 | B37: ESCAVADEIRA HIDRÁULICA SOBRE ESTEIRAS, CAÇAMBA 1,20 M3, PESO OPERACIONAL 21 T, POTÊNCIA BRUTA 155 HP - CHP DIURNO. AF_06/2014 | C37: SINAPI | D37: CHP | E37: 0.0042 | F37: ='COMPOSICOES AUXILIARES'!G1992 | G37: =TRUNC(TRUNC(E37,8)*F37,2) | L37: 0.0042 | M37: 262.65 | N37: =(M37-F37)
E38: TOTAL Equipamento Custo Horário: | G38: =SUM(G34:G37)
E39: VALOR: | G39: =SUM(G38)
E40: VALOR BDI (23.08%): | G40: =ROUNDDOWN(G39*BDI,2)
E41: VALOR COM BDI: | G41: =G40 + G39
A43: 2.1.1.3. ​95877​ TRANSPORTE COM CAMINHÃO BASCULANTE DE 18 M³, EM VIA URBANA PAVIMENTADA, DMT ATÉ 30 KM (UNIDADE:M3XKM). AF_07/2020​ (M3XKM)
A44: Equipamento Custo Horário | C44: FONTE | D44: UNID | E44: COEFICIENTE | F44: PREÇO UNITÁRIO | G44: TOTAL
A45: 89884 | B45: CAMINHÃO BASCULANTE 18 M3, COM CAVALO MECÂNICO DE CAPACIDADE MÁXIMA DE TRAÇÃO COMBINADO DE 45000 KG, POTÊNCIA 330 CV, INCLUSIVE SEMIREBOQUE COM CAÇAMBA METÁLICA - CHI DIURNO. AF_12/2014 | C45: SINAPI | D45: CHI | E45: 0.002 | F45: ='COMPOSICOES AUXILIARES'!G738 | G45: =TRUNC(TRUNC(E45,8)*F45,2) | L45: 0.002 | M45: 98.1 | N45: =(M45-F45)
...

Sheet COMPOSICOES AUXILIARES
A3: ​C0034​ ADIÇÃO DE IMPERMEABILIZANTE PARA CONCRETO ESTRUTURAL​ (M3)
A4: Material | C4: FONTE | D4: UNID | E4: COEFICIENTE | F4: PREÇO UNITÁRIO | G4: TOTAL
A5: I2421 | B5: SIKA 1 | C5: SEINFRA | D5: KG | E5: 7.92 | F5: =ROUND(M5*FATOR, 2) | G5: =ROUND(ROUND(E5,8)*F5,4) | L5: 7.92 | M5: 7 | N5: =(M5-F5)
E6: TOTAL Material: | G6: =SUM(G5:G5)
E7: VALOR: | G7: =SUM(G6)
E8: VALOR BDI (23.08%): | G8: =ROUNDDOWN(G7*BDI,2)
E9: VALOR COM BDI: | G9: =G8 + G7
A11: ​88238​ AJUDANTE DE ARMADOR COM ENCARGOS COMPLEMENTARES​ (H)
A12: Encargos Complementares | C12: FONTE | D12: UNID | E12: COEFICIENTE | F12: PREÇO UNITÁRIO | G12: TOTAL
A13: 00037370 | B13: ALIMENTACAO - HORISTA (COLETADO CAIXA - ENCARGOS COMPLEMENTARES) | C13: SINAPI | D13: H | E13: 1 | F13: 3.62 | G13: =TRUNC(TRUNC(E13,8)*F13,2) | L13: 1 | M13: 3.62 | N13: =(M13-F13)
A14: 00043489 | B14: EPI - FAMILIA PEDREIRO - HORISTA (ENCARGOS COMPLEMENTARES - COLETADO CAIXA) | C14: SINAPI | D14: H | E14: 1 | F14: 1.31 | G14: =TRUNC(TRUNC(E14,8)*F14,2) | L14: 1 | M14: 1.31 | N14: =(M14-F14)
A15: 00037372 | B15: EXAMES - HORISTA (COLETADO CAIXA - ENCARGOS COMPLEMENTARES) | C15: SINAPI | D15: H | E15: 1 | F15: 1.43 | G15: =TRUNC(TRUNC(E15,8)*F15,2) | L15: 1 | M15: 1.43 | N15: =(M15-F15)
A16: 00043465 | B16: FERRAMENTAS - FAMILIA PEDREIRO - HORISTA (ENCARGOS COMPLEMENTARES - COLETADO CAIXA) | C16: SINAPI | D16: H | E16: 1 | F16: 0.78 | G16: =TRUNC(TRUNC(E16,8)*F16,2) | L16: 1 | M16: 0.78 | N16: =(M16-F16)
A17: 00037373 | B17: SEGURO - HORISTA (COLETADO CAIXA - ENCARGOS COMPLEMENTARES) | C17: SINAPI | D17: H | E17: 1 | F17: 0.08 | G17: =TRUNC(TRUNC(E17,8)*F17,2) | L17: 1 | M17: 0.08 | N17: =(M17-F17)
A18: 00037371 | B18: TRANSPORTE - HORISTA (COLETADO CAIXA - ENCARGOS COMPLEMENTARES) | C18: SINAPI | D18: H | E18: 1 | F18: 1.09 | G18: =TRUNC(TRUNC(E18,8)*F18,2) | L18: 1 | M18: 1.09 | N18: =(M18-F18)
E19: TOTAL Encargos Complementares: | G19: =SUM(G13:G18)
A20: Mão de Obra | C20: FONTE | D20: UNID | E20: COEFICIENTE | F20: PREÇO UNITÁRIO | G20: TOTAL
A21: 00006114 | B21: AJUDANTE DE ARMADOR (HORISTA) | C21: SINAPI | D21: H | E21: =L21*FATOR | F21: 16.28 | G21: =TRUNC(TRUNC(E21,8)*F21,2) | L21: 1 | M21: 16.28 | N21: =(M21-F21)
E22: TOTAL Mão de Obra: | G22: =SUM(G21:G21)
A23: Serviço | C23: FONTE | D23: UNID | E23: COEFICIENTE | F23: PREÇO UNITÁRIO | G23: TOTAL
A24: 95308 | B24: CURSO DE CAPACITAÇÃO PARA AJUDANTE DE ARMADOR (ENCARGOS COMPLEMENTARES) - HORISTA | C24: SINAPI | D24: H | E24: 1 | F24: =G1483 | G24: =TRUNC(TRUNC(E24,8)*F24,2) | L24: 1 | M24: 0.18 | N24: =(M24-F24)
E25: TOTAL Serviço: | G25: =SUM(G24:G24)
E26: VALOR: | G26: =SUM(G25,G19,G22)
E27: VALOR BDI (23.08%): | G27: =ROUNDDOWN(G26*BDI,2)
E28: VALOR COM BDI: | G28: =G27 + G26
A30: ​ED-50363​ AJUDANTE DE BOMBEIRO/ENCANADOR COM ENCARGOS COMPLEMENTARES​ (hora)
A31: MÃO DE OBRA | D31: UNID | E31: CONSUMO | F31: SALÁRIO HORA | G31: CUSTO HORÁRIO
A32: MOED-20131 | B32: AJUDANTE DE BOMBEIRO/ ENCANADOR (MODALIDADE: HORISTA| ENCARGOS | D32: h | E32: =L32*FATOR | F32: 18.232 | G32: =ROUND(ROUND(E32,7)*F32,4) | L32: 1 | M32: 18.232 | N32: =(M32-F32)
E33: TOTAL MÃO DE OBRA: | G33: =SUM(G32:G32)
E34: Custo Horário da Execução: | G34: =G33
E35: Produção da Equipe: | G35: 1
E36: Custo Unitário da Execução: | G36: =ROUND(G34/G35, 4)
A37: MATERIAIS | D37: UNID | E37: CONSUMO | F37: =G700 | G37: CUSTO UNITÁRIO
A38: MATED-13096 | B38: CESTA BÁSICA/ALIMENTAÇÃO - HORISTA ( ENCARGOS COMPLEMENTARES) | D38: hora | E38: 1 | F38: 2.12 | G38: =ROUND(ROUND(E38,7)*F38,4) | L38: 1 | M38: 2.12 | N38: =(M38-F38)
A39: MATED-13099 | B39: EXAMES - HORISTA (ENCARGOS COMPLEMENTARES) | D39: hora | E39: 1 | F39: 1.43 | G39: =ROUND(ROUND(E39,7)*F39,4) | L39: 1 | M39: 1.43 | N39: =(M39-F39)
A40: MATED-13098 | B40: SEGURO - HORISTA (ENCARGOS COMPLEMENTARES) | D40: hora | E40: 1 | F40: 0.08 | G40: =ROUND(ROUND(E40,7)*F40,4) | L40: 1 | M40: 0.08 | N40: =(M40-F40)
A41: MATED-13097 | B41: TRANSPORTE - HORISTA (ENCARGOS COMPLEMENTARES) | D41: hora | E41: 1 | F41: 0.86 | G41: =ROUND(ROUND(E41,7)*F41,4) | L41: 1 | M41: 0.86 | N41: =(M41-F41)
E42: TOTAL MATERIAIS: | G42: =SUM(G38:G41)
A43: SERVIÇOS | D43: UNID | E43: CONSUMO | F43: PREÇO UNITÁRIO | G43: CUSTO UNITÁRIO
A44: ED-5227 | B44: CURSO DE CAPACITAÇÃO PARA AUXILIAR DE ENCANADOR OU BOMBEIRO HIDRÁULICO ( ENCARGOS COMPLEMENTARES) - HORISTA | D44: hora | E44: 1 | F44: 0.33 | G44: =ROUND(ROUND(E44,7)*F44,4) | L44: 1 | M44: 0.33 | N44: =(M44-F44)
...

Sheet ENCARGOS SOCIAIS
A3: COD | B3: DESCRIÇÃO | C3: HORISTA % | E3: MENSALISTA %
A5: A | B5: GRUPO A
A6: A1 | B6: INSS | C6: 20 | E6: 20
A7: A2 | B7: SESI | C7: 1.5 | E7: 1.5
A8: A3 | B8: SENAI | C8: 1 | E8: 1
A9: A4 | B9: INCRA | C9: 0.2 | E9: 0.2
A10: A5 | B10: SEBRAE | C10: 0.6 | E10: 0.6
A11: A6 | B11: Salário Educação | C11: 2.5 | E11: 2.5
A12: A7 | B12: Seguro Contra Acidentes de Trabalho | C12: 3 | E12: 3
A13: A8 | B13: FGTS | C13: 8 | E13: 8
A14: A9 | B14: SECONCI | C14: 0 | E14: 0
B15: TOTAL | C15: 36.8 | E15: 36.8
A17: B | B17: GRUPO B
A18: B1 | B18: Repouso Semanal Remunerado | C18: 17.85 | E18: 0
A19: B2 | B19: Feriados | C19: 3.71 | E19: 0
A20: B3 | B20: Auxíl io - Enfermidade | C20: 0.87 | E20: 0.66
A21: B4 | B21: 13º Salário | C21: 11.03 | E21: 8.33
A22: B5 | B22: Licença Paternidade | C22: 0.07 | E22: 0.05
A23: B6 | B23: Faltas Justificadas | C23: 0.74 | E23: 0.56
A24: B7 | B24: Dias de Chuvas | C24: 1.59 | E24: 0
A25: B8 | B25: Auxíl io Acidente de Trabalho | C25: 0.11 | E25: 0.08
A26: B9 | B26: Férias Gozadas | C26: 12.35 | E26: 9.33
A27: B10 | B27: Salário Maternidade | C27: 0.04 | E27: 0.03
B28: TOTAL | C28: 48.36 | E28: 19.04
A30: C | B30: GRUPO C
A31: C1 | B31: Aviso Prévio Indenizado | C31: 5.52 | E31: 4.17
A32: C2 | B32: Aviso Prévio Trabalhado | C32: 0.13 | E32: 0.1
A33: C3 | B33: Férias Indenizadas | C33: 1.72 | E33: 1.3
A34: C4 | B34: Depósito Rescisão Sem Justa Causa | C34: 2.87 | E34: 2.17
A35: C5 | B35: Indenização Adicional | C35: 0.46 | E35: 0.35
B36: TOTAL | C36: 10.7 | E36: 8.09
A38: D | B38: GRUPO D
A39: D1 | B39: Reincidência de Grupo A sobre Grupo B | C39: 17.8 | E39: 7.01
A40: D2 | B40: Reincidência de Grupo A sobre Aviso Prévio Trabalhado e Reincidência do FGTS sobre Aviso Prévio Indenizado | C40: 0.49 | E40: 0.37
B41: TOTAL | C41: 18.29 | E41: 7.38
B43: A + B + C + D = | C43: 114.15 | E43: 71.31
A45: COD | B45: DESCRIÇÃO | C45: HORISTA % | E45: MENSALISTA %
A47: A | B47: GRUPO A
A48: A1 | B48: INSS | C48: 20 | E48: 20
A49: A2 | B49: SESI | C49: 1.5 | E49: 1.5
...
